---
alias:
---


### Error 处理

#### 概述

如果一个 promise 正常 resolve，`await promise` 返回的就是其结果。但是如果 promise 被 reject，它将 throw 这个 error，就像在这一行有一个 `throw` 语句那样。

```javascript
//下面两段代码是一样的:

async function f() {
  await Promise.reject(new Error('whoops'));
}


async function f() {
  throw new Error('whoops');
}
```



#### 处理

在真实开发中，promise 可能需要一点时间后才 reject。在这种情况下，在 `await` 抛出（throw）一个 error 之前会有一个延时。

* 可以用 `try..catch` 来捕获上面提到的那个 error，与常规的 `throw` 使用的是一样的方式：
* try 可以包装多行 await 代码
* 没有使用`try...catch`,可以在函数调用后面添加`.catch` 来处理这个error

```javascript
//try...catch
async function f() {
  try {
    let response = await fetch('http://no-such-url');
  } catch (e) {
    alert(e); //TypeError: failed to fetch
  }
}

f();
```



```javascript
//try 包含多行await

async function f() {
  try {
    let response = await fetch('/no-user-here');
    let user = await response.json();
  } catch (e) {
    //捕获 fetch 和 response.json 中的错误
    alert(e);
  }
}

f();
```



```javascript
//使用.catch来处理

async function f() {
  let response = await fetch('http://no-such-url');
}

//f()变成一个rejected的promise
f().catch(alert); // TypeError: failed to fetch
```









```js
await等的是右侧「表达式」的结果
右侧如果是函数，那么函数的return值就是「表达式的结果」
右侧如果是一个 'hello' 或者什么值，那表达式的结果就是 'hello'

async function async1() {
    console.log( 'async1 start' )
    await async2()
    console.log( 'async1 end' )
}
async function async2() {
    console.log( 'async2' )
}
async1()
console.log( 'script start' )

上面例子中， 'async2' 和 'script start' 谁先打印呢？
实践的结论是，从右向左的。先打印async2，后打印的script start

await 等到之后,对于await来说，分2个情况:不是promise对象,是promise对象

如果不是 promise , await会阻塞后面的代码，先执行async外面的同步代码，同步代码执行完，再回到async内部，把这个非promise的东西，作为 await表达式的结果

如果它等到的是一个 promise 对象，await 也会暂停async后面的代码，先执行async外面的同步代码，等着 Promise 对象 fulfilled，然后把 resolve 的参数作为 await 表达式的运算结果。

分析一下 await async2()
前文提过await，1.它先计算出右侧的结果，2.然后看到await后，中断async函数

先得到await右侧表达式的结果。执行async2()，打印同步代码console.log('async2'), 并且return Promise.resolve(undefined)
await后，中断async函数，先执行async外的同步代码
目前就直接打印 console.log('async2')

回到async内部，执行await Promise.resolve(undefined)
如果一个 Promise 被传递给一个 await 操作符，await 将等待 Promise 正常处理完成并返回其处理结果。
在我们这个例子中，就是Promise.resolve(undefined)正常处理完成，并返回其处理结果。那么await async2()就算是执行结束了。
目前这个promise的状态是fulfilled，等其处理结果返回就可以执行await下面的代码了。

那何时能拿到处理结果呢？
需要在then的第一个参数里，才能拿到结果。
所以这里的 await Promise.resolve() 就类似于 Promise.resolve(undefined).then((undefined) => {})
把then的第一个回调参数 (undefined) => {} 推入微任务队列。then执行完，才是await async2()执行结束。
await async2()执行结束，才能继续执行后面的代码

```


