---
aliases: then, catch, finally,Promise.prototype.finally
---


### 原型方法

#### Promise.prototype.then()

Promise实例具有then方法,也就是说,then方法是定义在原型对象上的.

**作用**: 为Promise实例添加状态改变时的回调函数.

**参数**: then方法的第一个参数是Promise实例resolved状态时调用的回调函数,第二个参数是rejected状态时调用的回调函数,都是可选的.

**返回值**: **then方法返回一个新的Promise实例**(注意,不是原来的Promise实例). 因此可以采用链式写法, 即then方法后再调用一个then方法.

前一个回调函数，有可能返回的还是一个`Promise`对象（即有异步操作），这时后一个回调函数，就会等待该`Promise`对象的状态发生变化，才会被调用。

**注意事项**  值穿透现象
在Promise的then()函数或者catch()函数中，接收的是一个函数，函数的参数是resolve()函数或者reject()函数的返回值。而如果传入的值是非函数，那么就会产生值穿透现象。
何为值穿透现象？简单点理解就是then/catch中只有传入的是函数时候才会将返回值传递给下一个链式调用. 传递的非函数值会被直接忽略掉，继续执行链式调用后续的函数。
```js
Promise.resolve(1)
    .then(2)
    .then(Promise.resolve(3))
    .then(console.log);


Promise.resolve(1) 
	.then(() => { return 2 }) 
	.then(() => { return 3 }) 
	.then(console.log) //3

Promise.resolve(1) 
	.then(function () { return 2 }) 
	.then(() => { Promise.resolve(3) }) 
	.then(console.log) //undefined
```
第三个then()函数因为接收到console.log()函数，因此会执行，此时接收的是最开始的resolve(1)的值，因此场景5最终会输出“1”。



#### Promise.prototype.catch()

Promise.prototype.catch()是then(null, rejection)或then(undefined, rejection)的别名,用于指定发生错误时的回调函数.

```javascript
const promise = new Promise(function(resolve, reject) {
  throw new Error('test');
});

promise.catch(function(err) {
  console.log(error);
});

//Error: test
```

上面代码中，`promise`抛出一个错误，就被`catch()`方法指定的回调函数捕获。注意，上面的写法与下面两种写法是等价的。

```javascript
//写法一

const promise = new Promise(function(resolve, reject) {
  try {
    throw new Error('test');
  } catch(e) {
    reject(e);
  }
});

promise.catch(function(error) {
  console.log(error);
});

//写法二
const promise = new Promise(function(resolve, reject) {
  reject(new Error('test'));
});

promise.catch(function(error) {
  console.log(error);
})
```

比较上面两种写法，可以发现<u>`reject()`方法的作用，等同于抛出错误。</u>

如果Promise状态已经变成resolved, 再抛出错误是无效的.

```javascript
const promise = new Promise(function(resolve, reject) {
  resolve('ok');
  throw new Error('test');
});

promise
	.then(function(value) { console.log(value) })
	.catch(function(error) { console.log(error) });
```

上面代码中，Promise 在`resolve`语句后面，再抛出错误，不会被捕获，等于没有抛出。因为 Promise 的状态一旦改变，就永久保持该状态，不会再变了。

Promise 对象的错误具有“冒泡”性质，会一直向后传递，直到被捕获为止。也就是说，错误总是会被下一个`catch`语句捕获。

```javascript
getJSON('/post/1.json').then(function(post) {
  return getJSON(post.commentURL);
}).then(function(comments) {
  // some code
}).catch(function(error) {
  // 处理前面三个Promise产生的错误
});
```

上面代码中，一共有三个 Promise 对象：一个由`getJSON()`产生，两个由`then()`产生。它们之中任何一个抛出的错误，都会被最后一个`catch()`捕获。

一般来说，<u>不要在`then()`方法里面定义 Reject 状态的回调函数（即`then`的第二个参数）</u>，总是使用`catch`方法。

```javascript
//bad
promise
	.then(function(data) {
  //success
}, function(err) {
  //error
});

//good
promise
	.then(function(data) {
  	//success
	})
	.catch(function(err) {
  	//error
	});
```

上面代码中，第二种写法要好于第一种写法，理由是第二种写法可以捕获前面`then`方法执行中的错误，也更接近同步的写法（`try/catch`）。因此，建议总是使用`catch()`方法，而不使用`then()`方法的第二个参数。



**与try/catch比较**

跟传统的`try/catch`代码块不同的是，<span style="background:#ccc">如果没有使用`catch()`方法指定错误处理的回调函数，Promise 对象抛出的错误不会传递到外层代码，即不会有任何反应。</span>

```javascript
const someAsyncThing = function() {
  return new Promise(function(resolve, reject) {
    //下面一行会报错,因为x没有声明
    resolve(x + 2);
  });
};

someAsyncThing().then(function() {
  console.log('everything is great');
});

setTimeout(() => { console.log(123) }, 2000);
//Uncaught (in promise) ReferenceError: x is not defined
//123
```

上面代码中，`someAsyncThing()`函数产生的 Promise 对象，内部有语法错误。浏览器运行到这一行，会打印出错误提示`ReferenceError: x is not defined`，但是不会退出进程、终止脚本执行，2 秒之后还是会输出`123`。这就是说，<u>Promise 内部的错误不会影响到 Promise 外部的代码，通俗的说法就是“Promise 会吃掉错误”。</u>

再比如:

```javascript
const promise = new Promise(function(resolve, reject) {
  resolve('ok');
  setTimeout(function() {throw new Error('tset')}, 0)
});
promise.then(function(value) { console.log(value) });

//ok
//Uncaught Error: test
```

上面代码中，Promise 指定在下一轮“事件循环”再抛出错误。到了那个时候，Promise 的运行已经结束了，所以这个错误是在 Promise 函数体外抛出的，会冒泡到最外层，成了未捕获的错误。

一般建议, Promise 对象后面要跟`catch()`方法，这样可以处理 Promise 内部发生的错误。<span style="background:#ccc">`catch()`方法返回的还是一个 Promise 对象</span>，因此后面还可以接着调用`then()`方法。

```javascript
const someAsyncThing = function() {
  return new Promise(function(resolve, reject) {
    //下面一行代码会报错,因为x没有声明
    resolve(x + 2);
  });
};

someAsyncThing()
.catch(function(error) {
  console.log('oh, no', error);
})
.then(function() {
  console.log('carry on');
});

// oh no, [RefferenceError: x is not defined]
// carry on
```

上面代码运行完`catch()`方法指定的回调函数，会接着运行后面那个`then()`方法指定的回调函数。如果没有报错，则会跳过`catch()`方法。

```javascript
Promise.resolve()
.catch(function(error) {
  console.log('oh no', error);
})
.then(function() {
  console.log('carry on');
});
// carry on
```

catch方法之中还能再抛出错误

```javascript
const someAsyncThing = function() {
  return new Promise(function(resolve, reject) {
    // 下面一行会报错，因为x没有声明
    resolve(x + 2);
  });
};

someAsyncThing().then(function() {
  return someOtherAsyncThing();
}).catch(function(error) {
  console.log('oh no', error);
  // 下面一行会报错，因为 y 没有声明
  y + 2;
}).then(function() {
  console.log('carry on');
});
// oh no [ReferenceError: x is not defined]
```

上面代码中，`catch()`方法抛出一个错误，因为后面没有别的`catch()`方法了，导致这个错误不会被捕获，也不会传递到外层。如果改写一下，结果就不一样了。

```javascript
someAsyncThing().then(function() {
  return someOtherAsyncThing();
}).catch(function(error) {
  console.log('oh no', error);
  // 下面一行会报错，因为y没有声明
  y + 2;
}).catch(function(error) {
  console.log('carry on', error);
});
// oh no [ReferenceError: x is not defined]
// carry on [ReferenceError: y is not defined]
```

第二个`catch()`方法用来捕获前一个`catch()`方法抛出的错误。



#### Promise.prototype.finally()

the method returns a `Promise`. when the promises is finally either fulfilled or rejected, the specified callback function is executed. this provides a way for code to be run whether the promise was fulfilled successfully, or instead rejected.

**Syntax**

```javascript 
p.finally(onFinally)

p.finally(function() {
  //settled
})
```

**parameters**

`onFinally`

* A function called when the `Promise` is settled.

**Return values**

> returns a `Promise` whose `finally` handler is set to the specified function, `onFinally`.
>
> 我觉的这句话说的非常模糊.

**Desc**

如果你想在 promise 执行完毕后无论其结果怎样都做一些处理或清理时，`finally()` 方法可能是有用的。

`finally()` 虽然与 `.then(onFinally, onFinally)` 类似，它们不同的是：

- 调用内联函数时，不需要多次声明该函数或为该函数创建一个变量保存它。
- 由于无法知道`promise`的最终状态，所以`finally`的回调函数中不接收任何参数，它仅用于无论最终结果如何都要执行的情况。
- 与`Promise.resolve(2).then(() => {}, () => {})` （resolved的结果为`undefined`）不同，`Promise.resolve(2).finally(() => {})` resolved的结果为 `2`。
- 同样，`Promise.reject(3).then(() => {}, () => {})` (fulfilled的结果为`undefined`), `Promise.reject(3).finally(() => {})` rejected 的结果为 `3`。

> Note:  在finally回调中 throw (或返回被闪退的promise) 将以 throw() 指定的原因拒绝新的promise.



`finally`方法的回调函数不接受任何参数，这意味着没有办法知道，前面的 Promise 状态到底是`fulfilled`还是`rejected`。这表明，`finally`方法里面的操作，应该是与状态无关的，不依赖于 Promise 的执行结果。

`finally`本质上是`then`方法的特例。

```javascript
promise
.finally(() => {
  //语句
})

//等同于
promise
.then(result => {
  //语句
  return result;
}),
  error => {
  //语句
  throw error;
}
```

上面代码中，如果不使用`finally`方法，同样的语句需要为成功和失败两种情况各写一次。有了`finally`方法，则只需要写一次。

它的实现也很简单。

 ```javascript
Promise.prototype.finally = function(callback) {
  let P = this.constructor;
  return this.then(
  	value => P.resolve(callback()).then(() =>vlaue),
    reason => P.resolve(callback()).then(() =>{ throw reason })
  );
};
 ```

上面代码中，不管前面的 Promise 是`fulfilled`还是`rejected`，都会执行回调函数`callback`。

从上面的实现还可以看到，`finally`方法总是会返回原来的值。????

```javascript
// resolve 的值是 undefined
Promise.resolve(2).then(() => {}, () => {})

// resolve 的值是 2
Promise.resolve(2).finally(() => {})

// reject 的值是 undefined
Promise.reject(3).then(() => {}, () => {})

// reject 的值是 3
Promise.reject(3).finally(() => {})
```

**实现Promise.finally**

```javascript
Promise.prototoype.Finally = function(cb) {
  return this.then(
    (value) => {
    	return Promise.resolve(cb()).then(() => value)
  }, (err) => {
    	return Promise.resolve(cb()).then(() => throw err)
  })
}
```



```javascript
Promise.prototype.finally = function(cb) {
  return this.then(
    val => Promise.resolve(cb()).then(() => val),
    err => Promise.resolve(cb()).then(() => throw err)
  )
}
```
